[25/Sep/2013 19:59:47] ERROR [django.request:212] Internal Server Error: /findGroups/
Traceback (most recent call last):
  File "/home/nikolay/envs/anmec2/local/lib/python2.7/site-packages/django/core/handlers/base.py", line 115, in get_response
    response = callback(request, *callback_args, **callback_kwargs)
  File "/home/nikolay/envs/anmec2/local/lib/python2.7/site-packages/django/contrib/auth/decorators.py", line 25, in _wrapped_view
    return view_func(request, *args, **kwargs)
  File "/home/nikolay/envs/anmec2/local/lib/python2.7/site-packages/django/views/generic/base.py", line 68, in view
    return self.dispatch(request, *args, **kwargs)
  File "/home/nikolay/envs/anmec2/local/lib/python2.7/site-packages/django/views/generic/base.py", line 86, in dispatch
    return handler(request, *args, **kwargs)
  File "/home/nikolay/Desktop/anmec2/server/src/libs/anmec_utils/decorators.py", line 11, in wrapper
    return HttpResponse(json.dumps(func(*args, **kwargs)))
  File "/home/nikolay/Desktop/anmec2/server/src/search/views.py", line 220, in post
    gids = list(gids_queryset[offset:offset + results_per_page])
  File "/home/nikolay/envs/anmec2/local/lib/python2.7/site-packages/django/db/models/query.py", line 92, in __len__
    self._result_cache.extend(self._iter)
  File "/home/nikolay/envs/anmec2/local/lib/python2.7/site-packages/django/db/models/query.py", line 344, in _safe_iterator
    for item in iterator:
  File "/home/nikolay/envs/anmec2/local/lib/python2.7/site-packages/django/db/models/query.py", line 1138, in iterator
    for row in self.query.get_compiler(self.db).results_iter():
  File "/home/nikolay/envs/anmec2/local/lib/python2.7/site-packages/django/db/models/sql/compiler.py", line 775, in results_iter
    for rows in self.execute_sql(MULTI):
  File "/home/nikolay/envs/anmec2/local/lib/python2.7/site-packages/django/db/models/sql/compiler.py", line 830, in execute_sql
    sql, params = self.as_sql()
  File "/home/nikolay/envs/anmec2/local/lib/python2.7/site-packages/django/db/models/sql/compiler.py", line 75, in as_sql
    ordering, ordering_group_by = self.get_ordering()
  File "/home/nikolay/envs/anmec2/local/lib/python2.7/site-packages/django/db/models/sql/compiler.py", line 394, in get_ordering
    self.query.model._meta, default_order=asc):
  File "/home/nikolay/envs/anmec2/local/lib/python2.7/site-packages/django/db/models/sql/compiler.py", line 420, in find_ordering_name
    field, col, alias, joins, opts = self._setup_joins(pieces, opts, alias)
  File "/home/nikolay/envs/anmec2/local/lib/python2.7/site-packages/django/db/models/sql/compiler.py", line 453, in _setup_joins
    opts, alias, False)
  File "/home/nikolay/envs/anmec2/local/lib/python2.7/site-packages/django/db/models/sql/query.py", line 1325, in setup_joins
    "Choices are: %s" % (name, ", ".join(names)))
FieldError: Cannot resolve keyword u'undefinedmembers_count' into field. Choices are: audience, city, country, gid, is_closed, members_count, name, trafficbycities, trafficbycountries, type
[02/Oct/2013 22:34:13] ERROR [django.request:212] Internal Server Error: /findGroups/
Traceback (most recent call last):
  File "/home/nikolay/envs/anmec2/local/lib/python2.7/site-packages/django/core/handlers/base.py", line 115, in get_response
    response = callback(request, *callback_args, **callback_kwargs)
  File "/home/nikolay/envs/anmec2/local/lib/python2.7/site-packages/django/contrib/auth/decorators.py", line 25, in _wrapped_view
    return view_func(request, *args, **kwargs)
  File "/home/nikolay/envs/anmec2/local/lib/python2.7/site-packages/django/views/generic/base.py", line 68, in view
    return self.dispatch(request, *args, **kwargs)
  File "/home/nikolay/envs/anmec2/local/lib/python2.7/site-packages/django/views/generic/base.py", line 86, in dispatch
    return handler(request, *args, **kwargs)
  File "/home/nikolay/Desktop/anmec2/server/src/libs/anmec_utils/decorators.py", line 11, in wrapper
    return HttpResponse(json.dumps(func(*args, **kwargs)))
  File "/home/nikolay/Desktop/anmec2/server/src/search/views.py", line 202, in post
    form = SearchGroupsForm(data=request.body)
  File "/home/nikolay/Desktop/anmec2/server/src/libs/jsonforms/forms.py", line 42, in __init__
    parsed_data = self._flatten_dict(parsed_data)
  File "/home/nikolay/Desktop/anmec2/server/src/libs/jsonforms/forms.py", line 15, in _flatten_dict
    for key in dictionary.keys():
AttributeError: 'bool' object has no attribute 'keys'
[02/Oct/2013 22:34:14] ERROR [django.request:212] Internal Server Error: /findGroups/
Traceback (most recent call last):
  File "/home/nikolay/envs/anmec2/local/lib/python2.7/site-packages/django/core/handlers/base.py", line 115, in get_response
    response = callback(request, *callback_args, **callback_kwargs)
  File "/home/nikolay/envs/anmec2/local/lib/python2.7/site-packages/django/contrib/auth/decorators.py", line 25, in _wrapped_view
    return view_func(request, *args, **kwargs)
  File "/home/nikolay/envs/anmec2/local/lib/python2.7/site-packages/django/views/generic/base.py", line 68, in view
    return self.dispatch(request, *args, **kwargs)
  File "/home/nikolay/envs/anmec2/local/lib/python2.7/site-packages/django/views/generic/base.py", line 86, in dispatch
    return handler(request, *args, **kwargs)
  File "/home/nikolay/Desktop/anmec2/server/src/libs/anmec_utils/decorators.py", line 11, in wrapper
    return HttpResponse(json.dumps(func(*args, **kwargs)))
  File "/home/nikolay/Desktop/anmec2/server/src/search/views.py", line 202, in post
    form = SearchGroupsForm(data=request.body)
  File "/home/nikolay/Desktop/anmec2/server/src/libs/jsonforms/forms.py", line 42, in __init__
    parsed_data = self._flatten_dict(parsed_data)
  File "/home/nikolay/Desktop/anmec2/server/src/libs/jsonforms/forms.py", line 15, in _flatten_dict
    for key in dictionary.keys():
AttributeError: 'bool' object has no attribute 'keys'
[02/Oct/2013 22:34:15] ERROR [django.request:212] Internal Server Error: /findGroups/
Traceback (most recent call last):
  File "/home/nikolay/envs/anmec2/local/lib/python2.7/site-packages/django/core/handlers/base.py", line 115, in get_response
    response = callback(request, *callback_args, **callback_kwargs)
  File "/home/nikolay/envs/anmec2/local/lib/python2.7/site-packages/django/contrib/auth/decorators.py", line 25, in _wrapped_view
    return view_func(request, *args, **kwargs)
  File "/home/nikolay/envs/anmec2/local/lib/python2.7/site-packages/django/views/generic/base.py", line 68, in view
    return self.dispatch(request, *args, **kwargs)
  File "/home/nikolay/envs/anmec2/local/lib/python2.7/site-packages/django/views/generic/base.py", line 86, in dispatch
    return handler(request, *args, **kwargs)
  File "/home/nikolay/Desktop/anmec2/server/src/libs/anmec_utils/decorators.py", line 11, in wrapper
    return HttpResponse(json.dumps(func(*args, **kwargs)))
  File "/home/nikolay/Desktop/anmec2/server/src/search/views.py", line 202, in post
    form = SearchGroupsForm(data=request.body)
  File "/home/nikolay/Desktop/anmec2/server/src/libs/jsonforms/forms.py", line 42, in __init__
    parsed_data = self._flatten_dict(parsed_data)
  File "/home/nikolay/Desktop/anmec2/server/src/libs/jsonforms/forms.py", line 15, in _flatten_dict
    for key in dictionary.keys():
AttributeError: 'bool' object has no attribute 'keys'
[02/Oct/2013 22:43:24] ERROR [django.request:212] Internal Server Error: /findGroups/
Traceback (most recent call last):
  File "/home/nikolay/envs/anmec2/local/lib/python2.7/site-packages/django/core/handlers/base.py", line 115, in get_response
    response = callback(request, *callback_args, **callback_kwargs)
  File "/home/nikolay/envs/anmec2/local/lib/python2.7/site-packages/django/contrib/auth/decorators.py", line 25, in _wrapped_view
    return view_func(request, *args, **kwargs)
  File "/home/nikolay/envs/anmec2/local/lib/python2.7/site-packages/django/views/generic/base.py", line 68, in view
    return self.dispatch(request, *args, **kwargs)
  File "/home/nikolay/envs/anmec2/local/lib/python2.7/site-packages/django/views/generic/base.py", line 86, in dispatch
    return handler(request, *args, **kwargs)
  File "/home/nikolay/Desktop/anmec2/server/src/libs/anmec_utils/decorators.py", line 11, in wrapper
    return HttpResponse(json.dumps(func(*args, **kwargs)))
  File "/home/nikolay/Desktop/anmec2/server/src/search/views.py", line 214, in post
    gids_queryset = self.apply_basic_filters(gids_queryset, data)
  File "/home/nikolay/Desktop/anmec2/server/src/search/views.py", line 214, in post
    gids_queryset = self.apply_basic_filters(gids_queryset, data)
  File "/usr/lib/python2.7/bdb.py", line 49, in trace_dispatch
    return self.dispatch_line(frame)
  File "/usr/lib/python2.7/bdb.py", line 68, in dispatch_line
    if self.quitting: raise BdbQuit
BdbQuit
[02/Oct/2013 22:50:37] ERROR [django.request:212] Internal Server Error: /findGroups/
Traceback (most recent call last):
  File "/home/nikolay/envs/anmec2/local/lib/python2.7/site-packages/django/core/handlers/base.py", line 115, in get_response
    response = callback(request, *callback_args, **callback_kwargs)
  File "/home/nikolay/envs/anmec2/local/lib/python2.7/site-packages/django/contrib/auth/decorators.py", line 25, in _wrapped_view
    return view_func(request, *args, **kwargs)
  File "/home/nikolay/envs/anmec2/local/lib/python2.7/site-packages/django/views/generic/base.py", line 68, in view
    return self.dispatch(request, *args, **kwargs)
  File "/home/nikolay/envs/anmec2/local/lib/python2.7/site-packages/django/views/generic/base.py", line 86, in dispatch
    return handler(request, *args, **kwargs)
  File "/home/nikolay/Desktop/anmec2/server/src/libs/anmec_utils/decorators.py", line 11, in wrapper
    return HttpResponse(json.dumps(func(*args, **kwargs)))
  File "/home/nikolay/Desktop/anmec2/server/src/search/views.py", line 229, in post
    city_traffic = self.get_city_traffic(gids, data)
  File "/home/nikolay/Desktop/anmec2/server/src/search/views.py", line 229, in post
    city_traffic = self.get_city_traffic(gids, data)
  File "/usr/lib/python2.7/bdb.py", line 49, in trace_dispatch
    return self.dispatch_line(frame)
  File "/usr/lib/python2.7/bdb.py", line 68, in dispatch_line
    if self.quitting: raise BdbQuit
BdbQuit
[02/Oct/2013 22:52:30] ERROR [django.request:212] Internal Server Error: /findGroups/
Traceback (most recent call last):
  File "/home/nikolay/envs/anmec2/local/lib/python2.7/site-packages/django/core/handlers/base.py", line 115, in get_response
    response = callback(request, *callback_args, **callback_kwargs)
  File "/home/nikolay/envs/anmec2/local/lib/python2.7/site-packages/django/contrib/auth/decorators.py", line 24, in _wrapped_view
    if test_func(request.user):
  File "/home/nikolay/envs/anmec2/local/lib/python2.7/site-packages/django/contrib/auth/decorators.py", line 50, in <lambda>
    lambda u: u.is_authenticated(),
  File "/home/nikolay/envs/anmec2/local/lib/python2.7/site-packages/django/utils/functional.py", line 202, in inner
    self._setup()
  File "/home/nikolay/envs/anmec2/local/lib/python2.7/site-packages/django/utils/functional.py", line 268, in _setup
    self._wrapped = self._setupfunc()
  File "/home/nikolay/envs/anmec2/local/lib/python2.7/site-packages/django/contrib/auth/middleware.py", line 18, in <lambda>
    request.user = SimpleLazyObject(lambda: get_user(request))
  File "/home/nikolay/envs/anmec2/local/lib/python2.7/site-packages/django/contrib/auth/middleware.py", line 10, in get_user
    request._cached_user = auth.get_user(request)
  File "/home/nikolay/envs/anmec2/local/lib/python2.7/site-packages/django/contrib/auth/__init__.py", line 134, in get_user
    user_id = request.session[SESSION_KEY]
  File "/home/nikolay/envs/anmec2/local/lib/python2.7/site-packages/django/contrib/sessions/backends/base.py", line 46, in __getitem__
    return self._session[key]
  File "/home/nikolay/envs/anmec2/local/lib/python2.7/site-packages/django/contrib/sessions/backends/base.py", line 168, in _get_session
    self._session_cache = self.load()
  File "/home/nikolay/envs/anmec2/local/lib/python2.7/site-packages/django/contrib/sessions/backends/db.py", line 18, in load
    expire_date__gt=timezone.now()
  File "/home/nikolay/envs/anmec2/local/lib/python2.7/site-packages/django/db/models/manager.py", line 143, in get
    return self.get_query_set().get(*args, **kwargs)
  File "/home/nikolay/envs/anmec2/local/lib/python2.7/site-packages/django/db/models/query.py", line 394, in get
    num = len(clone)
  File "/home/nikolay/envs/anmec2/local/lib/python2.7/site-packages/django/db/models/query.py", line 90, in __len__
    self._result_cache = list(self.iterator())
  File "/home/nikolay/envs/anmec2/local/lib/python2.7/site-packages/django/db/models/query.py", line 301, in iterator
    for row in compiler.results_iter():
  File "/home/nikolay/envs/anmec2/local/lib/python2.7/site-packages/django/db/models/sql/compiler.py", line 775, in results_iter
    for rows in self.execute_sql(MULTI):
  File "/home/nikolay/envs/anmec2/local/lib/python2.7/site-packages/django/db/models/sql/compiler.py", line 839, in execute_sql
    cursor = self.connection.cursor()
  File "/home/nikolay/envs/anmec2/local/lib/python2.7/site-packages/django/db/backends/__init__.py", line 324, in cursor
    cursor = self.make_debug_cursor(self._cursor())
  File "/home/nikolay/envs/anmec2/local/lib/python2.7/site-packages/django/db/backends/postgresql_psycopg2/base.py", line 182, in _cursor
    self.connection = Database.connect(**conn_params)
  File "/home/nikolay/envs/anmec2/local/lib/python2.7/site-packages/psycopg2/__init__.py", line 178, in connect
    return _connect(dsn, connection_factory=connection_factory, async=async)
OperationalError: FATAL:  database "anmec" does not exist

[02/Oct/2013 22:52:30] ERROR [django.request:212] Internal Server Error: /findGroups/
Traceback (most recent call last):
  File "/home/nikolay/envs/anmec2/local/lib/python2.7/site-packages/django/core/handlers/base.py", line 115, in get_response
    response = callback(request, *callback_args, **callback_kwargs)
  File "/home/nikolay/envs/anmec2/local/lib/python2.7/site-packages/django/contrib/auth/decorators.py", line 24, in _wrapped_view
    if test_func(request.user):
  File "/home/nikolay/envs/anmec2/local/lib/python2.7/site-packages/django/contrib/auth/decorators.py", line 50, in <lambda>
    lambda u: u.is_authenticated(),
  File "/home/nikolay/envs/anmec2/local/lib/python2.7/site-packages/django/utils/functional.py", line 202, in inner
    self._setup()
  File "/home/nikolay/envs/anmec2/local/lib/python2.7/site-packages/django/utils/functional.py", line 268, in _setup
    self._wrapped = self._setupfunc()
  File "/home/nikolay/envs/anmec2/local/lib/python2.7/site-packages/django/contrib/auth/middleware.py", line 18, in <lambda>
    request.user = SimpleLazyObject(lambda: get_user(request))
  File "/home/nikolay/envs/anmec2/local/lib/python2.7/site-packages/django/contrib/auth/middleware.py", line 10, in get_user
    request._cached_user = auth.get_user(request)
  File "/home/nikolay/envs/anmec2/local/lib/python2.7/site-packages/django/contrib/auth/__init__.py", line 134, in get_user
    user_id = request.session[SESSION_KEY]
  File "/home/nikolay/envs/anmec2/local/lib/python2.7/site-packages/django/contrib/sessions/backends/base.py", line 46, in __getitem__
    return self._session[key]
  File "/home/nikolay/envs/anmec2/local/lib/python2.7/site-packages/django/contrib/sessions/backends/base.py", line 168, in _get_session
    self._session_cache = self.load()
  File "/home/nikolay/envs/anmec2/local/lib/python2.7/site-packages/django/contrib/sessions/backends/db.py", line 18, in load
    expire_date__gt=timezone.now()
  File "/home/nikolay/envs/anmec2/local/lib/python2.7/site-packages/django/db/models/manager.py", line 143, in get
    return self.get_query_set().get(*args, **kwargs)
  File "/home/nikolay/envs/anmec2/local/lib/python2.7/site-packages/django/db/models/query.py", line 394, in get
    num = len(clone)
  File "/home/nikolay/envs/anmec2/local/lib/python2.7/site-packages/django/db/models/query.py", line 90, in __len__
    self._result_cache = list(self.iterator())
  File "/home/nikolay/envs/anmec2/local/lib/python2.7/site-packages/django/db/models/query.py", line 301, in iterator
    for row in compiler.results_iter():
  File "/home/nikolay/envs/anmec2/local/lib/python2.7/site-packages/django/db/models/sql/compiler.py", line 775, in results_iter
    for rows in self.execute_sql(MULTI):
  File "/home/nikolay/envs/anmec2/local/lib/python2.7/site-packages/django/db/models/sql/compiler.py", line 839, in execute_sql
    cursor = self.connection.cursor()
  File "/home/nikolay/envs/anmec2/local/lib/python2.7/site-packages/django/db/backends/__init__.py", line 324, in cursor
    cursor = self.make_debug_cursor(self._cursor())
  File "/home/nikolay/envs/anmec2/local/lib/python2.7/site-packages/django/db/backends/postgresql_psycopg2/base.py", line 182, in _cursor
    self.connection = Database.connect(**conn_params)
  File "/home/nikolay/envs/anmec2/local/lib/python2.7/site-packages/psycopg2/__init__.py", line 178, in connect
    return _connect(dsn, connection_factory=connection_factory, async=async)
OperationalError: FATAL:  database "anmec" does not exist

[02/Oct/2013 22:52:30] ERROR [django.request:212] Internal Server Error: /account/summary/
Traceback (most recent call last):
  File "/home/nikolay/envs/anmec2/local/lib/python2.7/site-packages/django/core/handlers/base.py", line 115, in get_response
    response = callback(request, *callback_args, **callback_kwargs)
  File "/home/nikolay/envs/anmec2/local/lib/python2.7/site-packages/django/views/generic/base.py", line 68, in view
    return self.dispatch(request, *args, **kwargs)
  File "/home/nikolay/envs/anmec2/local/lib/python2.7/site-packages/django/views/generic/base.py", line 86, in dispatch
    return handler(request, *args, **kwargs)
  File "/home/nikolay/Desktop/anmec2/server/src/libs/anmec_utils/decorators.py", line 11, in wrapper
    return HttpResponse(json.dumps(func(*args, **kwargs)))
  File "/home/nikolay/Desktop/anmec2/server/src/./account/views.py", line 97, in get
    if not request.user.is_authenticated():
  File "/home/nikolay/envs/anmec2/local/lib/python2.7/site-packages/django/utils/functional.py", line 202, in inner
    self._setup()
  File "/home/nikolay/envs/anmec2/local/lib/python2.7/site-packages/django/utils/functional.py", line 268, in _setup
    self._wrapped = self._setupfunc()
  File "/home/nikolay/envs/anmec2/local/lib/python2.7/site-packages/django/contrib/auth/middleware.py", line 18, in <lambda>
    request.user = SimpleLazyObject(lambda: get_user(request))
  File "/home/nikolay/envs/anmec2/local/lib/python2.7/site-packages/django/contrib/auth/middleware.py", line 10, in get_user
    request._cached_user = auth.get_user(request)
  File "/home/nikolay/envs/anmec2/local/lib/python2.7/site-packages/django/contrib/auth/__init__.py", line 134, in get_user
    user_id = request.session[SESSION_KEY]
  File "/home/nikolay/envs/anmec2/local/lib/python2.7/site-packages/django/contrib/sessions/backends/base.py", line 46, in __getitem__
    return self._session[key]
  File "/home/nikolay/envs/anmec2/local/lib/python2.7/site-packages/django/contrib/sessions/backends/base.py", line 168, in _get_session
    self._session_cache = self.load()
  File "/home/nikolay/envs/anmec2/local/lib/python2.7/site-packages/django/contrib/sessions/backends/db.py", line 18, in load
    expire_date__gt=timezone.now()
  File "/home/nikolay/envs/anmec2/local/lib/python2.7/site-packages/django/db/models/manager.py", line 143, in get
    return self.get_query_set().get(*args, **kwargs)
  File "/home/nikolay/envs/anmec2/local/lib/python2.7/site-packages/django/db/models/query.py", line 394, in get
    num = len(clone)
  File "/home/nikolay/envs/anmec2/local/lib/python2.7/site-packages/django/db/models/query.py", line 90, in __len__
    self._result_cache = list(self.iterator())
  File "/home/nikolay/envs/anmec2/local/lib/python2.7/site-packages/django/db/models/query.py", line 301, in iterator
    for row in compiler.results_iter():
  File "/home/nikolay/envs/anmec2/local/lib/python2.7/site-packages/django/db/models/sql/compiler.py", line 775, in results_iter
    for rows in self.execute_sql(MULTI):
  File "/home/nikolay/envs/anmec2/local/lib/python2.7/site-packages/django/db/models/sql/compiler.py", line 839, in execute_sql
    cursor = self.connection.cursor()
  File "/home/nikolay/envs/anmec2/local/lib/python2.7/site-packages/django/db/backends/__init__.py", line 324, in cursor
    cursor = self.make_debug_cursor(self._cursor())
  File "/home/nikolay/envs/anmec2/local/lib/python2.7/site-packages/django/db/backends/postgresql_psycopg2/base.py", line 182, in _cursor
    self.connection = Database.connect(**conn_params)
  File "/home/nikolay/envs/anmec2/local/lib/python2.7/site-packages/psycopg2/__init__.py", line 178, in connect
    return _connect(dsn, connection_factory=connection_factory, async=async)
OperationalError: FATAL:  database "anmec" does not exist

[02/Oct/2013 22:54:01] ERROR [django.request:212] Internal Server Error: /account/summary/
Traceback (most recent call last):
  File "/home/nikolay/envs/anmec2/local/lib/python2.7/site-packages/django/core/handlers/base.py", line 115, in get_response
    response = callback(request, *callback_args, **callback_kwargs)
  File "/home/nikolay/envs/anmec2/local/lib/python2.7/site-packages/django/views/generic/base.py", line 68, in view
    return self.dispatch(request, *args, **kwargs)
  File "/home/nikolay/envs/anmec2/local/lib/python2.7/site-packages/django/views/generic/base.py", line 86, in dispatch
    return handler(request, *args, **kwargs)
  File "/home/nikolay/Desktop/anmec2/server/src/libs/anmec_utils/decorators.py", line 11, in wrapper
    return HttpResponse(json.dumps(func(*args, **kwargs)))
  File "/home/nikolay/Desktop/anmec2/server/src/./account/views.py", line 97, in get
    if not request.user.is_authenticated():
  File "/home/nikolay/envs/anmec2/local/lib/python2.7/site-packages/django/utils/functional.py", line 202, in inner
    self._setup()
  File "/home/nikolay/envs/anmec2/local/lib/python2.7/site-packages/django/utils/functional.py", line 268, in _setup
    self._wrapped = self._setupfunc()
  File "/home/nikolay/envs/anmec2/local/lib/python2.7/site-packages/django/contrib/auth/middleware.py", line 18, in <lambda>
    request.user = SimpleLazyObject(lambda: get_user(request))
  File "/home/nikolay/envs/anmec2/local/lib/python2.7/site-packages/django/contrib/auth/middleware.py", line 10, in get_user
    request._cached_user = auth.get_user(request)
  File "/home/nikolay/envs/anmec2/local/lib/python2.7/site-packages/django/contrib/auth/__init__.py", line 134, in get_user
    user_id = request.session[SESSION_KEY]
  File "/home/nikolay/envs/anmec2/local/lib/python2.7/site-packages/django/contrib/sessions/backends/base.py", line 46, in __getitem__
    return self._session[key]
  File "/home/nikolay/envs/anmec2/local/lib/python2.7/site-packages/django/contrib/sessions/backends/base.py", line 168, in _get_session
    self._session_cache = self.load()
  File "/home/nikolay/envs/anmec2/local/lib/python2.7/site-packages/django/contrib/sessions/backends/db.py", line 18, in load
    expire_date__gt=timezone.now()
  File "/home/nikolay/envs/anmec2/local/lib/python2.7/site-packages/django/db/models/manager.py", line 143, in get
    return self.get_query_set().get(*args, **kwargs)
  File "/home/nikolay/envs/anmec2/local/lib/python2.7/site-packages/django/db/models/query.py", line 394, in get
    num = len(clone)
  File "/home/nikolay/envs/anmec2/local/lib/python2.7/site-packages/django/db/models/query.py", line 90, in __len__
    self._result_cache = list(self.iterator())
  File "/home/nikolay/envs/anmec2/local/lib/python2.7/site-packages/django/db/models/query.py", line 301, in iterator
    for row in compiler.results_iter():
  File "/home/nikolay/envs/anmec2/local/lib/python2.7/site-packages/django/db/models/sql/compiler.py", line 775, in results_iter
    for rows in self.execute_sql(MULTI):
  File "/home/nikolay/envs/anmec2/local/lib/python2.7/site-packages/django/db/models/sql/compiler.py", line 839, in execute_sql
    cursor = self.connection.cursor()
  File "/home/nikolay/envs/anmec2/local/lib/python2.7/site-packages/django/db/backends/__init__.py", line 324, in cursor
    cursor = self.make_debug_cursor(self._cursor())
  File "/home/nikolay/envs/anmec2/local/lib/python2.7/site-packages/django/db/backends/postgresql_psycopg2/base.py", line 182, in _cursor
    self.connection = Database.connect(**conn_params)
  File "/home/nikolay/envs/anmec2/local/lib/python2.7/site-packages/psycopg2/__init__.py", line 178, in connect
    return _connect(dsn, connection_factory=connection_factory, async=async)
OperationalError: FATAL:  database "anmec" does not exist

[02/Oct/2013 22:54:01] ERROR [django.request:212] Internal Server Error: /findGroups/
Traceback (most recent call last):
  File "/home/nikolay/envs/anmec2/local/lib/python2.7/site-packages/django/core/handlers/base.py", line 115, in get_response
    response = callback(request, *callback_args, **callback_kwargs)
  File "/home/nikolay/envs/anmec2/local/lib/python2.7/site-packages/django/contrib/auth/decorators.py", line 24, in _wrapped_view
    if test_func(request.user):
  File "/home/nikolay/envs/anmec2/local/lib/python2.7/site-packages/django/contrib/auth/decorators.py", line 50, in <lambda>
    lambda u: u.is_authenticated(),
  File "/home/nikolay/envs/anmec2/local/lib/python2.7/site-packages/django/utils/functional.py", line 202, in inner
    self._setup()
  File "/home/nikolay/envs/anmec2/local/lib/python2.7/site-packages/django/utils/functional.py", line 268, in _setup
    self._wrapped = self._setupfunc()
  File "/home/nikolay/envs/anmec2/local/lib/python2.7/site-packages/django/contrib/auth/middleware.py", line 18, in <lambda>
    request.user = SimpleLazyObject(lambda: get_user(request))
  File "/home/nikolay/envs/anmec2/local/lib/python2.7/site-packages/django/contrib/auth/middleware.py", line 10, in get_user
    request._cached_user = auth.get_user(request)
  File "/home/nikolay/envs/anmec2/local/lib/python2.7/site-packages/django/contrib/auth/__init__.py", line 134, in get_user
    user_id = request.session[SESSION_KEY]
  File "/home/nikolay/envs/anmec2/local/lib/python2.7/site-packages/django/contrib/sessions/backends/base.py", line 46, in __getitem__
    return self._session[key]
  File "/home/nikolay/envs/anmec2/local/lib/python2.7/site-packages/django/contrib/sessions/backends/base.py", line 168, in _get_session
    self._session_cache = self.load()
  File "/home/nikolay/envs/anmec2/local/lib/python2.7/site-packages/django/contrib/sessions/backends/db.py", line 18, in load
    expire_date__gt=timezone.now()
  File "/home/nikolay/envs/anmec2/local/lib/python2.7/site-packages/django/db/models/manager.py", line 143, in get
    return self.get_query_set().get(*args, **kwargs)
  File "/home/nikolay/envs/anmec2/local/lib/python2.7/site-packages/django/db/models/query.py", line 394, in get
    num = len(clone)
  File "/home/nikolay/envs/anmec2/local/lib/python2.7/site-packages/django/db/models/query.py", line 90, in __len__
    self._result_cache = list(self.iterator())
  File "/home/nikolay/envs/anmec2/local/lib/python2.7/site-packages/django/db/models/query.py", line 301, in iterator
    for row in compiler.results_iter():
  File "/home/nikolay/envs/anmec2/local/lib/python2.7/site-packages/django/db/models/sql/compiler.py", line 775, in results_iter
    for rows in self.execute_sql(MULTI):
  File "/home/nikolay/envs/anmec2/local/lib/python2.7/site-packages/django/db/models/sql/compiler.py", line 839, in execute_sql
    cursor = self.connection.cursor()
  File "/home/nikolay/envs/anmec2/local/lib/python2.7/site-packages/django/db/backends/__init__.py", line 324, in cursor
    cursor = self.make_debug_cursor(self._cursor())
  File "/home/nikolay/envs/anmec2/local/lib/python2.7/site-packages/django/db/backends/postgresql_psycopg2/base.py", line 182, in _cursor
    self.connection = Database.connect(**conn_params)
  File "/home/nikolay/envs/anmec2/local/lib/python2.7/site-packages/psycopg2/__init__.py", line 178, in connect
    return _connect(dsn, connection_factory=connection_factory, async=async)
OperationalError: FATAL:  database "anmec" does not exist

[02/Oct/2013 22:54:01] ERROR [django.request:212] Internal Server Error: /findGroups/
Traceback (most recent call last):
  File "/home/nikolay/envs/anmec2/local/lib/python2.7/site-packages/django/core/handlers/base.py", line 115, in get_response
    response = callback(request, *callback_args, **callback_kwargs)
  File "/home/nikolay/envs/anmec2/local/lib/python2.7/site-packages/django/contrib/auth/decorators.py", line 24, in _wrapped_view
    if test_func(request.user):
  File "/home/nikolay/envs/anmec2/local/lib/python2.7/site-packages/django/contrib/auth/decorators.py", line 50, in <lambda>
    lambda u: u.is_authenticated(),
  File "/home/nikolay/envs/anmec2/local/lib/python2.7/site-packages/django/utils/functional.py", line 202, in inner
    self._setup()
  File "/home/nikolay/envs/anmec2/local/lib/python2.7/site-packages/django/utils/functional.py", line 268, in _setup
    self._wrapped = self._setupfunc()
  File "/home/nikolay/envs/anmec2/local/lib/python2.7/site-packages/django/contrib/auth/middleware.py", line 18, in <lambda>
    request.user = SimpleLazyObject(lambda: get_user(request))
  File "/home/nikolay/envs/anmec2/local/lib/python2.7/site-packages/django/contrib/auth/middleware.py", line 10, in get_user
    request._cached_user = auth.get_user(request)
  File "/home/nikolay/envs/anmec2/local/lib/python2.7/site-packages/django/contrib/auth/__init__.py", line 134, in get_user
    user_id = request.session[SESSION_KEY]
  File "/home/nikolay/envs/anmec2/local/lib/python2.7/site-packages/django/contrib/sessions/backends/base.py", line 46, in __getitem__
    return self._session[key]
  File "/home/nikolay/envs/anmec2/local/lib/python2.7/site-packages/django/contrib/sessions/backends/base.py", line 168, in _get_session
    self._session_cache = self.load()
  File "/home/nikolay/envs/anmec2/local/lib/python2.7/site-packages/django/contrib/sessions/backends/db.py", line 18, in load
    expire_date__gt=timezone.now()
  File "/home/nikolay/envs/anmec2/local/lib/python2.7/site-packages/django/db/models/manager.py", line 143, in get
    return self.get_query_set().get(*args, **kwargs)
  File "/home/nikolay/envs/anmec2/local/lib/python2.7/site-packages/django/db/models/query.py", line 394, in get
    num = len(clone)
  File "/home/nikolay/envs/anmec2/local/lib/python2.7/site-packages/django/db/models/query.py", line 90, in __len__
    self._result_cache = list(self.iterator())
  File "/home/nikolay/envs/anmec2/local/lib/python2.7/site-packages/django/db/models/query.py", line 301, in iterator
    for row in compiler.results_iter():
  File "/home/nikolay/envs/anmec2/local/lib/python2.7/site-packages/django/db/models/sql/compiler.py", line 775, in results_iter
    for rows in self.execute_sql(MULTI):
  File "/home/nikolay/envs/anmec2/local/lib/python2.7/site-packages/django/db/models/sql/compiler.py", line 839, in execute_sql
    cursor = self.connection.cursor()
  File "/home/nikolay/envs/anmec2/local/lib/python2.7/site-packages/django/db/backends/__init__.py", line 324, in cursor
    cursor = self.make_debug_cursor(self._cursor())
  File "/home/nikolay/envs/anmec2/local/lib/python2.7/site-packages/django/db/backends/postgresql_psycopg2/base.py", line 182, in _cursor
    self.connection = Database.connect(**conn_params)
  File "/home/nikolay/envs/anmec2/local/lib/python2.7/site-packages/psycopg2/__init__.py", line 178, in connect
    return _connect(dsn, connection_factory=connection_factory, async=async)
OperationalError: FATAL:  database "anmec" does not exist

[02/Oct/2013 22:56:44] ERROR [django.request:212] Internal Server Error: /account/summary/
Traceback (most recent call last):
  File "/home/nikolay/envs/anmec2/local/lib/python2.7/site-packages/django/core/handlers/base.py", line 115, in get_response
    response = callback(request, *callback_args, **callback_kwargs)
  File "/home/nikolay/envs/anmec2/local/lib/python2.7/site-packages/django/views/generic/base.py", line 68, in view
    return self.dispatch(request, *args, **kwargs)
  File "/home/nikolay/envs/anmec2/local/lib/python2.7/site-packages/django/views/generic/base.py", line 86, in dispatch
    return handler(request, *args, **kwargs)
  File "/home/nikolay/Desktop/anmec2/server/src/libs/anmec_utils/decorators.py", line 11, in wrapper
    return HttpResponse(json.dumps(func(*args, **kwargs)))
  File "/home/nikolay/Desktop/anmec2/server/src/./account/views.py", line 97, in get
    if not request.user.is_authenticated():
  File "/home/nikolay/envs/anmec2/local/lib/python2.7/site-packages/django/utils/functional.py", line 202, in inner
    self._setup()
  File "/home/nikolay/envs/anmec2/local/lib/python2.7/site-packages/django/utils/functional.py", line 268, in _setup
    self._wrapped = self._setupfunc()
  File "/home/nikolay/envs/anmec2/local/lib/python2.7/site-packages/django/contrib/auth/middleware.py", line 18, in <lambda>
    request.user = SimpleLazyObject(lambda: get_user(request))
  File "/home/nikolay/envs/anmec2/local/lib/python2.7/site-packages/django/contrib/auth/middleware.py", line 10, in get_user
    request._cached_user = auth.get_user(request)
  File "/home/nikolay/envs/anmec2/local/lib/python2.7/site-packages/django/contrib/auth/__init__.py", line 134, in get_user
    user_id = request.session[SESSION_KEY]
  File "/home/nikolay/envs/anmec2/local/lib/python2.7/site-packages/django/contrib/sessions/backends/base.py", line 46, in __getitem__
    return self._session[key]
  File "/home/nikolay/envs/anmec2/local/lib/python2.7/site-packages/django/contrib/sessions/backends/base.py", line 168, in _get_session
    self._session_cache = self.load()
  File "/home/nikolay/envs/anmec2/local/lib/python2.7/site-packages/django/contrib/sessions/backends/db.py", line 18, in load
    expire_date__gt=timezone.now()
  File "/home/nikolay/envs/anmec2/local/lib/python2.7/site-packages/django/db/models/manager.py", line 143, in get
    return self.get_query_set().get(*args, **kwargs)
  File "/home/nikolay/envs/anmec2/local/lib/python2.7/site-packages/django/db/models/query.py", line 394, in get
    num = len(clone)
  File "/home/nikolay/envs/anmec2/local/lib/python2.7/site-packages/django/db/models/query.py", line 90, in __len__
    self._result_cache = list(self.iterator())
  File "/home/nikolay/envs/anmec2/local/lib/python2.7/site-packages/django/db/models/query.py", line 301, in iterator
    for row in compiler.results_iter():
  File "/home/nikolay/envs/anmec2/local/lib/python2.7/site-packages/django/db/models/sql/compiler.py", line 775, in results_iter
    for rows in self.execute_sql(MULTI):
  File "/home/nikolay/envs/anmec2/local/lib/python2.7/site-packages/django/db/models/sql/compiler.py", line 840, in execute_sql
    cursor.execute(sql, params)
  File "/home/nikolay/envs/anmec2/local/lib/python2.7/site-packages/django/db/backends/util.py", line 41, in execute
    return self.cursor.execute(sql, params)
  File "/home/nikolay/envs/anmec2/local/lib/python2.7/site-packages/django/db/backends/postgresql_psycopg2/base.py", line 58, in execute
    six.reraise(utils.DatabaseError, utils.DatabaseError(*tuple(e.args)), sys.exc_info()[2])
  File "/home/nikolay/envs/anmec2/local/lib/python2.7/site-packages/django/db/backends/postgresql_psycopg2/base.py", line 54, in execute
    return self.cursor.execute(query, args)
DatabaseError: permission denied for relation django_session

[02/Oct/2013 22:56:44] ERROR [django.request:212] Internal Server Error: /findGroups/
Traceback (most recent call last):
  File "/home/nikolay/envs/anmec2/local/lib/python2.7/site-packages/django/core/handlers/base.py", line 115, in get_response
    response = callback(request, *callback_args, **callback_kwargs)
  File "/home/nikolay/envs/anmec2/local/lib/python2.7/site-packages/django/contrib/auth/decorators.py", line 24, in _wrapped_view
    if test_func(request.user):
  File "/home/nikolay/envs/anmec2/local/lib/python2.7/site-packages/django/contrib/auth/decorators.py", line 50, in <lambda>
    lambda u: u.is_authenticated(),
  File "/home/nikolay/envs/anmec2/local/lib/python2.7/site-packages/django/utils/functional.py", line 202, in inner
    self._setup()
  File "/home/nikolay/envs/anmec2/local/lib/python2.7/site-packages/django/utils/functional.py", line 268, in _setup
    self._wrapped = self._setupfunc()
  File "/home/nikolay/envs/anmec2/local/lib/python2.7/site-packages/django/contrib/auth/middleware.py", line 18, in <lambda>
    request.user = SimpleLazyObject(lambda: get_user(request))
  File "/home/nikolay/envs/anmec2/local/lib/python2.7/site-packages/django/contrib/auth/middleware.py", line 10, in get_user
    request._cached_user = auth.get_user(request)
  File "/home/nikolay/envs/anmec2/local/lib/python2.7/site-packages/django/contrib/auth/__init__.py", line 134, in get_user
    user_id = request.session[SESSION_KEY]
  File "/home/nikolay/envs/anmec2/local/lib/python2.7/site-packages/django/contrib/sessions/backends/base.py", line 46, in __getitem__
    return self._session[key]
  File "/home/nikolay/envs/anmec2/local/lib/python2.7/site-packages/django/contrib/sessions/backends/base.py", line 168, in _get_session
    self._session_cache = self.load()
  File "/home/nikolay/envs/anmec2/local/lib/python2.7/site-packages/django/contrib/sessions/backends/db.py", line 18, in load
    expire_date__gt=timezone.now()
  File "/home/nikolay/envs/anmec2/local/lib/python2.7/site-packages/django/db/models/manager.py", line 143, in get
    return self.get_query_set().get(*args, **kwargs)
  File "/home/nikolay/envs/anmec2/local/lib/python2.7/site-packages/django/db/models/query.py", line 394, in get
    num = len(clone)
  File "/home/nikolay/envs/anmec2/local/lib/python2.7/site-packages/django/db/models/query.py", line 90, in __len__
    self._result_cache = list(self.iterator())
  File "/home/nikolay/envs/anmec2/local/lib/python2.7/site-packages/django/db/models/query.py", line 301, in iterator
    for row in compiler.results_iter():
  File "/home/nikolay/envs/anmec2/local/lib/python2.7/site-packages/django/db/models/sql/compiler.py", line 775, in results_iter
    for rows in self.execute_sql(MULTI):
  File "/home/nikolay/envs/anmec2/local/lib/python2.7/site-packages/django/db/models/sql/compiler.py", line 840, in execute_sql
    cursor.execute(sql, params)
  File "/home/nikolay/envs/anmec2/local/lib/python2.7/site-packages/django/db/backends/util.py", line 41, in execute
    return self.cursor.execute(sql, params)
  File "/home/nikolay/envs/anmec2/local/lib/python2.7/site-packages/django/db/backends/postgresql_psycopg2/base.py", line 58, in execute
    six.reraise(utils.DatabaseError, utils.DatabaseError(*tuple(e.args)), sys.exc_info()[2])
  File "/home/nikolay/envs/anmec2/local/lib/python2.7/site-packages/django/db/backends/postgresql_psycopg2/base.py", line 54, in execute
    return self.cursor.execute(query, args)
DatabaseError: permission denied for relation django_session

[02/Oct/2013 22:56:44] ERROR [django.request:212] Internal Server Error: /findGroups/
Traceback (most recent call last):
  File "/home/nikolay/envs/anmec2/local/lib/python2.7/site-packages/django/core/handlers/base.py", line 115, in get_response
    response = callback(request, *callback_args, **callback_kwargs)
  File "/home/nikolay/envs/anmec2/local/lib/python2.7/site-packages/django/contrib/auth/decorators.py", line 24, in _wrapped_view
    if test_func(request.user):
  File "/home/nikolay/envs/anmec2/local/lib/python2.7/site-packages/django/contrib/auth/decorators.py", line 50, in <lambda>
    lambda u: u.is_authenticated(),
  File "/home/nikolay/envs/anmec2/local/lib/python2.7/site-packages/django/utils/functional.py", line 202, in inner
    self._setup()
  File "/home/nikolay/envs/anmec2/local/lib/python2.7/site-packages/django/utils/functional.py", line 268, in _setup
    self._wrapped = self._setupfunc()
  File "/home/nikolay/envs/anmec2/local/lib/python2.7/site-packages/django/contrib/auth/middleware.py", line 18, in <lambda>
    request.user = SimpleLazyObject(lambda: get_user(request))
  File "/home/nikolay/envs/anmec2/local/lib/python2.7/site-packages/django/contrib/auth/middleware.py", line 10, in get_user
    request._cached_user = auth.get_user(request)
  File "/home/nikolay/envs/anmec2/local/lib/python2.7/site-packages/django/contrib/auth/__init__.py", line 134, in get_user
    user_id = request.session[SESSION_KEY]
  File "/home/nikolay/envs/anmec2/local/lib/python2.7/site-packages/django/contrib/sessions/backends/base.py", line 46, in __getitem__
    return self._session[key]
  File "/home/nikolay/envs/anmec2/local/lib/python2.7/site-packages/django/contrib/sessions/backends/base.py", line 168, in _get_session
    self._session_cache = self.load()
  File "/home/nikolay/envs/anmec2/local/lib/python2.7/site-packages/django/contrib/sessions/backends/db.py", line 18, in load
    expire_date__gt=timezone.now()
  File "/home/nikolay/envs/anmec2/local/lib/python2.7/site-packages/django/db/models/manager.py", line 143, in get
    return self.get_query_set().get(*args, **kwargs)
  File "/home/nikolay/envs/anmec2/local/lib/python2.7/site-packages/django/db/models/query.py", line 394, in get
    num = len(clone)
  File "/home/nikolay/envs/anmec2/local/lib/python2.7/site-packages/django/db/models/query.py", line 90, in __len__
    self._result_cache = list(self.iterator())
  File "/home/nikolay/envs/anmec2/local/lib/python2.7/site-packages/django/db/models/query.py", line 301, in iterator
    for row in compiler.results_iter():
  File "/home/nikolay/envs/anmec2/local/lib/python2.7/site-packages/django/db/models/sql/compiler.py", line 775, in results_iter
    for rows in self.execute_sql(MULTI):
  File "/home/nikolay/envs/anmec2/local/lib/python2.7/site-packages/django/db/models/sql/compiler.py", line 840, in execute_sql
    cursor.execute(sql, params)
  File "/home/nikolay/envs/anmec2/local/lib/python2.7/site-packages/django/db/backends/util.py", line 41, in execute
    return self.cursor.execute(sql, params)
  File "/home/nikolay/envs/anmec2/local/lib/python2.7/site-packages/django/db/backends/postgresql_psycopg2/base.py", line 58, in execute
    six.reraise(utils.DatabaseError, utils.DatabaseError(*tuple(e.args)), sys.exc_info()[2])
  File "/home/nikolay/envs/anmec2/local/lib/python2.7/site-packages/django/db/backends/postgresql_psycopg2/base.py", line 54, in execute
    return self.cursor.execute(query, args)
DatabaseError: permission denied for relation django_session

[02/Oct/2013 22:58:28] ERROR [django.request:212] Internal Server Error: /account/summary/
Traceback (most recent call last):
  File "/home/nikolay/envs/anmec2/local/lib/python2.7/site-packages/django/core/handlers/base.py", line 115, in get_response
    response = callback(request, *callback_args, **callback_kwargs)
  File "/home/nikolay/envs/anmec2/local/lib/python2.7/site-packages/django/views/generic/base.py", line 68, in view
    return self.dispatch(request, *args, **kwargs)
  File "/home/nikolay/envs/anmec2/local/lib/python2.7/site-packages/django/views/generic/base.py", line 86, in dispatch
    return handler(request, *args, **kwargs)
  File "/home/nikolay/Desktop/anmec2/server/src/libs/anmec_utils/decorators.py", line 11, in wrapper
    return HttpResponse(json.dumps(func(*args, **kwargs)))
  File "/home/nikolay/Desktop/anmec2/server/src/./account/views.py", line 97, in get
    if not request.user.is_authenticated():
  File "/home/nikolay/envs/anmec2/local/lib/python2.7/site-packages/django/utils/functional.py", line 202, in inner
    self._setup()
  File "/home/nikolay/envs/anmec2/local/lib/python2.7/site-packages/django/utils/functional.py", line 268, in _setup
    self._wrapped = self._setupfunc()
  File "/home/nikolay/envs/anmec2/local/lib/python2.7/site-packages/django/contrib/auth/middleware.py", line 18, in <lambda>
    request.user = SimpleLazyObject(lambda: get_user(request))
  File "/home/nikolay/envs/anmec2/local/lib/python2.7/site-packages/django/contrib/auth/middleware.py", line 10, in get_user
    request._cached_user = auth.get_user(request)
  File "/home/nikolay/envs/anmec2/local/lib/python2.7/site-packages/django/contrib/auth/__init__.py", line 134, in get_user
    user_id = request.session[SESSION_KEY]
  File "/home/nikolay/envs/anmec2/local/lib/python2.7/site-packages/django/contrib/sessions/backends/base.py", line 46, in __getitem__
    return self._session[key]
  File "/home/nikolay/envs/anmec2/local/lib/python2.7/site-packages/django/contrib/sessions/backends/base.py", line 168, in _get_session
    self._session_cache = self.load()
  File "/home/nikolay/envs/anmec2/local/lib/python2.7/site-packages/django/contrib/sessions/backends/db.py", line 18, in load
    expire_date__gt=timezone.now()
  File "/home/nikolay/envs/anmec2/local/lib/python2.7/site-packages/django/db/models/manager.py", line 143, in get
    return self.get_query_set().get(*args, **kwargs)
  File "/home/nikolay/envs/anmec2/local/lib/python2.7/site-packages/django/db/models/query.py", line 394, in get
    num = len(clone)
  File "/home/nikolay/envs/anmec2/local/lib/python2.7/site-packages/django/db/models/query.py", line 90, in __len__
    self._result_cache = list(self.iterator())
  File "/home/nikolay/envs/anmec2/local/lib/python2.7/site-packages/django/db/models/query.py", line 301, in iterator
    for row in compiler.results_iter():
  File "/home/nikolay/envs/anmec2/local/lib/python2.7/site-packages/django/db/models/sql/compiler.py", line 775, in results_iter
    for rows in self.execute_sql(MULTI):
  File "/home/nikolay/envs/anmec2/local/lib/python2.7/site-packages/django/db/models/sql/compiler.py", line 839, in execute_sql
    cursor = self.connection.cursor()
  File "/home/nikolay/envs/anmec2/local/lib/python2.7/site-packages/django/db/backends/__init__.py", line 324, in cursor
    cursor = self.make_debug_cursor(self._cursor())
  File "/home/nikolay/envs/anmec2/local/lib/python2.7/site-packages/django/db/backends/postgresql_psycopg2/base.py", line 182, in _cursor
    self.connection = Database.connect(**conn_params)
  File "/home/nikolay/envs/anmec2/local/lib/python2.7/site-packages/psycopg2/__init__.py", line 178, in connect
    return _connect(dsn, connection_factory=connection_factory, async=async)
OperationalError: FATAL:  password authentication failed for user "anmec"
FATAL:  password authentication failed for user "anmec"

